Workbook

Sheet KOL SocMed 
F3: KIM
A11: Date | B11: : 03 Nov 2025 - Rev 18 | E11: Project | F11: : Ingram Micro Innovation Day 2025
A12: Attn | B12: : Abigail Laurencia | E12: Date | F12: : 09 Dec 2025 (Tues)
A13: Client | B13: : PT Ingram Micro Indonesia | E13: Venue | F13: : Shangri-La Hotel, Jakarta
A14: Address | B14: : Jl. Ir. H. Juanda IV No 3B-C | E14: No. Order | F14: : QTN/KIM/2025/VIII/00015 B
B15: Wisma Nugra Santana Lt. 9 Suite 909
B16: Jakarta Pusat 10250
E18: KIM
A19: NO | B19: DESCRIPTION | C19: QTY | D19: Freq | E19: Price-unit | F19: Sub Total
A21: A | B21: Ingram Micro Innovation Day 2025
B22: Digital Creator & Soc Med Package
A24: 1 | B24: Design : Social Media Content , masih tunggu list timeline dari Cia | C24: 1 | D24: 1 | E24: 0 | F24: 0
B25: Video Teaser - done
B26: Quote Dewi
A29: 2 | B29: Content Creators
B30: Anjas Maradita - Tech Reviewer - SOW sbb | C30: 1 | D30: 1 | E30: 30000000 | F30: =C30*D30*E30 -> 30000000
B31: - Visit Event & Attend Podcast pas Coffe Break dan Lunch Time
B32: - Live Streaming Podcast di Youtube
B33: - IG Story 1x (post ig reels) (after Event)
B34: - 1x IG Reels (after Event, keseruan Acara)
B35: KOL Coordination (KOL Brief, Coordination, On Event Supervision) | C35: 1 | D35: 1 | E35: 1000000 | F35: =C35*D35*E35 -> 1000000
B36: Yoan Full Day
F38: =SUM(F20:F37) -> 31000000
B39: Sub Total | F39: =+F38 -> 31000000
A48: Note (Contract, Term & Condition) :
A49: 1 | B49: The Price Included PPn 11 %
A50: 2 | B50: Approval needed latest one month before in related to 3rd party
A51: 3 | B51: Cancellation fee 25 % from total amount of the project if the contract has been signed
A52: 4 | B52: Term of payment :
B53: 100 % payment after project finish
B54: Payment Transfer to : PT Kemenangan Indah Makmur
B55: Bank BCA Branch : Pondok Indah
B56: account IDR : 731.065.558.3
B57: account USD : 731.096.766.6
B58: NPWP : 02.098.562.8-013.000
B61: Prepared by : | F61: Approved by,
B68: Fanny Suwarni | F68: Abigail Laurencia
B69: KIM Marketing Services | F69: PT Ingram Micro Indonesia

Sheet PR Package BEM
F3: KIM
A11: Date | B11: : 03 Nov 2025 - Rev 18 | E11: Project | F11: : Ingram Micro Innovation Day 2025
A12: Attn | B12: : Abigail Laurencia | E12: Date | F12: : 09 Dec 2025 (Tues)
A13: Client | B13: : PT Ingram Micro Indonesia | E13: Venue | F13: : Shangri-La Hotel, Jakarta
A14: Address | B14: : Jl. Ir. H. Juanda IV No 3B-C | E14: No. Order | F14: : QTN/KIM/2025/VIII/00015 C
B15: Wisma Nugra Santana Lt. 9 Suite 909
B16: Jakarta Pusat 10250
A21: NO | B21: DESCRIPTION | C21: PIC | D21: QTY | E21: Freq | F21: Price-unit | G21: Sub Total | I21: MBTH - JGN HPS
A23: A | B23: C-Level & PR Event
A24: 1 | B24: D Day: Media Press Conference | C24: KIM | D24: 1 | E24: 1 | F24: 45000000 | G24: =D24*E24*F24 -> 45000000
B25: Media Invite (40 media)
B26: Follow up media relations activity
B27: Briefing Document for Speakers
I28: Media - Untuk media writing competition kita drop krna budget tidak masuk - 13/11
A30: 2 | B30: Post Event :Press Release (Service from Udari/KIM to IM) | C30: KIM | D30: 1 | E30: 1
B31: Press Release (Development - bilingual, and Distribution)
B32: Post Event Monitoring & Report
A34: B | B34: Production on the Day
B35: C-Level & Media Event
A37: 1 | B37: PREPARATION
B38: Supervision Hotel from preparation ( h-1 ) - Loading Unloading | C38: KIM | D38: 1 | E38: 1 | G38: =D38*E38*F38 -> 0
A40: 2 | B40: SHOW MANAGEMENT for Full Day event: C-Level & PR) | C40: KIM | D40: 1 | E40: 1 | G40: =D40*E40*F40 -> 0
B41: Project Officer | C41: KIM | D41: 1 | E41: 1
B42: Show Management: Stage Manager, Crew MC, Stage Crew, VJ | C42: KIM | D42: 1 | E42: 2
B43: Eartac | C43: KIM | D43: 1 | E43: 1
B44: Registration | C44: KIM | D44: 2 | E44: 1
A46: 3 | B46: TALENT & Documentation : Half Day
B47: Photografer | C47: KIM | D47: 1 | E47: 1 | G47: =D47*E47*F47 -> 0
B48: Video For Documentation | C48: KIM | D48: 1 | E48: 1 | G48: =D48*E48*F48 -> 0
B49: MC Media: BEM | C49: KIM | D49: 1 | E49: 1 | G49: =D49*E49*F49 -> 0
A51: 4 | B51: Creative Package
B52: 2D Design (All Material Video Bumper) | C52: KIM | D52: 1 | E52: 1 | G52: =+D52*E52*F52 -> 0
A54: 5 | B54: Production
B55: Foyer Area:
B56: Signage Digital | C56: Hotel | D56: 1 | E56: 1 | G56: =+D56*E56*F56 -> 0
B58: Electrical & Audio Visual
B59: LED P2.6 size 2,5 x4m , with Base LED | C59: KIM | D59: 1 | E59: 1.5 | G59: =+D59*E59*F59 -> 0
B60: Clicker | C60: KIM | D60: 1 | E60: 1
B61: Soundsystem 1500 watt | C61: KIM | D61: 1 | E61: 1.5 | G61: =+D61*E61*F61 -> 0
B62: TV Matador | C62: KIM | D62: 1 | E62: 1.5 | G62: =D62*E62*F62 -> 0
...

Sheet Registration
G4: KIM
A12: Date | B12: : 03 Nov 2025 - Rev 18 | E12: Project | F12: : Ingram Micro Innovation Day 2025
A13: Attn | B13: : Abigail Laurencia | E13: Date | F13: : 09 Dec 2025 (Tues)
A14: Client | B14: : PT Ingram Micro Indonesia | E14: Venue | F14: : Shangri-La Hotel, Jakarta
A15: Address | B15: : Jl. Ir. H. Juanda IV No 3B-C | E15: No. Order | F15: : QTN/KIM/2025/VIII/00015 D
B16: Wisma Nugra Santana Lt. 9 Suite 909
B17: Jakarta Pusat 10250
A22: NO | B22: DESCRIPTION | C22: PIC | D22: QTY | E22: Freq | F22: Price-unit | G22: Sub Total
A23: 1 | B23: Microsite Customer & Partner - additional request for Content | C23: Michael | D23: 1 | E23: 1 | F23: 5000000 | G23: =D23*E23*F23 -> 5000000
B24: Registration, Self Checkin, System Booth Tour, Feedback form
A26: 2 | B26: Registration System | C26: Michael | D26: 1 | E26: 1 | F26: 3000000 | G26: =D26*E26*F26 -> 3000000 | I26: VIA WA CALL… KATANYA DIA ACC ITU 7,5 JUTA KENAPA SKRG 10JUTA? JD BALIKIN KE 7,5JUTA
B27: Registration equipment : Printer, Laptop include technician | C27: KIM | D27: 5 | E27: 1 | G27: =D27*E27*F27 -> 0 | I27: GW DAH CARI KE NO REV 17.. TULISANNYA TETEP 10JT… APA ADA BUKTI DIA ACC DI 7,5JUTA KAH?
B28: Leader registration | C28: KIM | D28: 1 | E28: 1 | G28: =D28*E28*F28 -> 0
B29: Usher Checkin | C29: KIM | D29: 2 | E29: 1 | G29: =D29*E29*F29 -> 0
B30: Usher Walkin | C30: KIM | D30: 2 | E30: 1 | G30: =D30*E30*F30 -> 0
B33: Sub Total | G33: =SUM(G23:G32) -> 8000000
A41: 2 | B41: Approval needed latest one month before in related to 3rd party
A42: 3 | B42: Cancellation fee 25 % from total amount of the project if the contract has been signed
A43: 4 | B43: Term of payment :
B44: 100 % payment after project finish
B45: Payment Transfer to : PT Kemenangan Indah Makmur
B46: Bank BCA Branch : Pondok Indah
B47: account IDR : 731.065.558.3
B48: account USD : 731.096.766.6
B49: NPWP : 02.098.562.8-013.000
B53: Prepared by : | G53: Approved by,
B60: Fanny Suwarni | G60: Abigail Laurencia
B61: KIM Marketing Services | G61: PT Ingram Micro Indonesia

Sheet Customer Event
G5: KIM
A13: Date | B13: : 03 Nov 2025 - Rev 18 | E13: Project | F13: : Ingram Micro Innovation Day 2025
A14: Attn | B14: : Abigail Laurencia | E14: Date | F14: : 09 Dec 2025 (Tues)
A15: Client | B15: : PT Ingram Micro Indonesia | E15: Venue | F15: : Shangri-La Hotel, Jakarta
A16: Address | B16: : Jl. Ir. H. Juanda IV No 3B-C | E16: No. Order | F16: : QTN/KIM/2025/VIII/00015 E
B17: Wisma Nugra Santana Lt. 9 Suite 909
B18: Jakarta Pusat 10250
F21: KIM
A22: NO | B22: DESCRIPTION | C22: PIC | D22: QTY | E22: Freq | F22: Price-unit | G22: Sub Total | I22: MBTH - JGN HPS
A24: A | B24: Ingram Micro Innovation Day 2025
B25: Customers Event
A27: 0 | B27: Venue : F& B Package
B28: Half Day Meeting Package
B29: Full Day Meeting Package
B30: Gala Dinner
B31: Free flow drink: Juice, Soft drink, Beer, Wine
A33: 1 | B33: PREPARATION
B34: Loading Unloading Team | C34: KIM | D34: 1 | E34: 1 | G34: =D34*E34*F34 -> 0
A36: 2 | B36: SHOW MANAGEMENT for Customer event + GR
B37: Project Officer | C37: KIM | D37: 1 | E37: 1 | G37: =D37*E37*F37 -> 0
B38: Customer Conference Session : Show Management: Stage Manager, Crew MC, Stage Crew, VJ, | C38: KIM | D38: 1 | E38: 1.5 | G38: =D38*E38*F38 -> 0
B39: LO Speaker - Long Shift dari C-Level - Partner Event | C39: KIM | D39: 1 | E39: 1 | G39: =D39*E39*F39 -> 0
B40: Asst LO Speaker - Sponsor | C40: KIM | D40: 1 | E40: 1 | G40: =D40*E40*F40 -> 0
B41: Eartac | C41: KIM | D41: 12 | E41: 1 | G41: =D41*E41*F41 -> 0
B42: HT | C42: KIM | D42: 15 | E42: 1 | G42: =D42*E42*F42 -> 0
B43: Perfect Que | C43: KIM | D43: 1 | E43: 1 | G43: =D43*E43*F43 -> 0
B44: Meals | C44: KIM | D44: 15 | E44: 1 | G44: =D44*E44*F44 -> 0
A46: 3 | B46: Documentation & Talent : 08.00 - 21.00
B47: Photografer | C47: FILBERT | D47: 1 | E47: 1 | G47: =D47*E47*F47 -> 0
B48: Video For Documentation | D48: 1 | E48: 1 | G48: =D48*E48*F48 -> 0
B49: Operator Livestream , Live Cam + 3 Camera = total 5 pax | C49: TMN koko | D49: 1 | E49: 1 | F49: 4500000 | G49: =D49*E49*F49 -> 4500000 | I49: =4500000+91836 -> 4591836 | J49: PAKET ALAT LIVESTREAMIN | K49: MALVIB | L49: 45968 | M49: ada filbert juga
B51: TALENT
B52: MC - Customer + Partner Dinner : Tya Ayustia | C52: KIM | D52: 1 | E52: 1 | F52: =I52 -> 15384615 | G52: =D52*E52*F52 -> 15384615 | I52: =15000000+384615 -> 15384615 | J52: MC | K52: YUSTIANI | L52: 45968
B53: MC - Gala Dinner : Rio Simamora | C53: KIM | D53: 1 | E53: 1 | G53: =D53*E53*F53 -> 0
B54: MC - Clevel, HD : Jessica William | C54: KIM | D54: 1 | E54: 1 | F54: 7500000 | G54: =D54*E54*F54 -> 7500000
B55: MC - Podcast, FD - Marcellona Siregar | C55: KIM | D55: 1 | E55: 1 | F55: =I55 -> 7692307 | G55: =D55*E55*F55 -> 7692307 | I55: =7500000+192307 -> 7692307 | J55: MC | K55: AZZARA | L55: 45968
B57: Keynote Indrawan Nugroho - 2x event : C-Level & Customer | C57: KIM | D57: 1 | E57: 1 | F57: 72500000 | G57: =D57*E57*F57 -> 72500000 | I57: =66000000+1346938 -> 67346938 | J57: SPEAKER | K57: PT. CIPTA KONSULTAN | L57: 45968
B59: Moderator Fireside Chat: Wisnu Nugroho Infokom | C59: KIM | D59: 1 | E59: 1 | F59: 4500000 | G59: =D59*E59*F59 -> 4500000
B60: Panelist:Joseph Lembayung | C60: KIM | D60: 1 | E60: 1 | F60: 5000000 | G60: =D60*E60*F60 -> 5000000
B62: Ushers - Black costume KIM | long Shift | C62: KIM | D62: 6 | E62: 1 | G62: =D62*E62*F62 -> 0
...

Sheet Partner Event
G6: KIM
A14: Date | B14: : 03 Nov 2025 - Rev 18 | F14: Project | G14: : Ingram Micro Innovation Day 2025
A15: Attn | B15: : Abigail Laurencia | F15: Date | G15: : 09 Dec 2025 (Tues)
A16: Client | B16: : PT Ingram Micro Indonesia | F16: Venue | G16: : Shangri-La Hotel, Jakarta
A17: Address | B17: : Jl. Ir. H. Juanda IV No 3B-C | F17: No. Order | G17: : QTN/KIM/2025/VIII/00015 F
B18: Wisma Nugra Santana Lt. 9 Suite 909
B19: Jakarta Pusat 10250
F22: KIM
A23: NO | B23: DESCRIPTION | C23: PIC | D23: QTY | E23: Freq | F23: Price-unit | G23: Sub Total | K23: MBTH - JGN HPS
A25: A | B25: Ingram Micro Innovation Day 2025
B26: Partner Gathering
A28: 2 | B28: SHOW MANAGEMENT for Partner event + GR
B29: Partner Session : Show Management: Stage Manager, Crew MC, Stage Crew, VJ, | C29: KIM | D29: 1 | E29: 1 | G29: =D29*E29*F29 -> 0
B30: Talent Coord | C30: KIM | D30: 1 | E30: 1 | G30: =D30*E30*F30 -> 0
B31: Meals | C31: KIM | D31: 15 | E31: 1 | G31: =D31*E31*F31 -> 0
A33: 3 | B33: TALENT
B34: Entertainment : Latte Matte - 120 mnt | C34: KIM | D34: 1 | E34: 1 | G34: =D34*E34*F34 -> 0
B35: Riders : Meals + drinks , Make Up Room | C35: KIM | D35: 1 | E35: 1 | G35: =D35*E35*F35 -> 0
B36: Alt : TBC
A38: 5 | B38: Creative
B39: Video Awarding 2D & sdikit 3D - 10 award | C39: Falah | D39: 1 | E39: 1 | F39: 9000000 | G39: =D39*E39*F39 -> 9000000
A41: 6 | B41: Award Thropy
B42: Plaque | C42: KIM | D42: 10 | E42: 1 | F42: 850000 | G42: =D42*E42*F42 -> 8500000 | K42: 8500000 | L42: PLAKAT 10 | M42: YOKI | N42: 45968
A44: 7 | B44: Other Cost
B45: Lanyard + Name Badge : Partner 350 | C45: KIM | D45: 350 | E45: 1 | G45: =D45*E45*F45 -> 0 | K45: 682564 | L45: NAME BADGE - 850 | M45: SHOPPEE | N45: 45968
B46: Concept | C46: KIM | D46: 1 | E46: 1 | G46: =D46*E46*F46 -> 0
B47: Photo Glambot - 6 hours only @ Partner Event | C47: KIM | D47: 1 | E47: 1 | G47: =D47*E47*F47 -> 0 | K47: =8500000+173469 -> 8673469 | L47: GLAMBOTH | M47: PT. VARBEL | N47: 45968
G48: =D48*E48*F48 -> 0
B49: Costume for Leader - Ika, bu Mira, Hotland, JT, Hendrik, Justin, Rio | C49: KIM | D49: =11+6-10 -> 7 | E49: 1 | G49: =D49*E49*F49 -> 0 | K49: =22500000+459184 -> 22959184 | L49: SEWA COSTUM LEADER N BU DEWI | M49: GALIH | N49: 45974 | P49: Men 11 , Female 6 | S49: update meeting 12/11 + 3
B50: Costume for bu Dewi | C50: KIM | D50: 1 | E50: 1 | F50: 2500000 | G50: =D50*E50*F50 -> 2500000
B51: MUA for Men | C51: KIM | D51: =11-6 -> 5 | E51: 1 | F51: 300000 | G51: =D51*E51*F51 -> 1500000 | K51: gw kaga ngarti mksdnya apa | M51: Partner - Untuk baju leader & make up sesuaikan hanya untuk bu dewi, ika, bu mira, hotland, JT, Hendrik, justin, rio - 13/11
B52: MUA for Female | C52: KIM | D52: =6-4 -> 2 | E52: 1 | F52: 500000 | G52: =D52*E52*F52 -> 1000000
B54: Meja LED for Laptop Prizes - Xvantage member | C54: KIM | D54: 3 | E54: 1 | G54: =D54*E54*F54 -> 0
B55: Signage | C55: KIM | D55: 1 | E55: 1 | G55: =D55*E55*F55 -> 0 | K55: dr roll up jadi signage | M55: 1500000 kayu dpt 2 pcs, tripod banner 3 @125rb
B56: - Signage Area | C56: KIM | D56: 2 | E56: 1
B57: - Tripod banner (laptop) | C57: KIM | D57: 3 | E57: 1
B59: Custome - Astronaut | C59: KIM | D59: 1 | E59: 1 | G59: =D59*E59*F59 -> 0 | K59: beli baju usher 9 org x 500rb
B60: Crew - utk laptop | C60: KIM | D60: 3 | E60: 1 | G60: =D60*E60*F60 -> 0 | M60: Partner - Usher astronut di hilangkan - 13/11
B61: Ipad | C61: KIM | D61: =3-1 -> 2 | E61: 1 | G61: =D61*E61*F61 -> 0 | M61: Partner - Ipad hanya 2 aja - 13/11
A63: 8 | B63: Additional:
...

Sheet Booth
A9: Date | B9: : 03 Nov 2025 - Rev 18 | F9: Project | G9: : Ingram Micro Innovation Day 2025
A10: Attn | B10: : Abigail Laurencia | F10: Date | G10: : 09 Dec 2025 (Tues)
A11: Client | B11: : PT Ingram Micro Indonesia | F11: Venue | G11: : Shangri-La Hotel, Jakarta
A12: Address | B12: : Jl. Ir. H. Juanda IV No 3B-C | F12: No. Order | G12: : QTN/KIM/2025/VIII/00015 A
B13: Wisma Nugra Santana Lt. 9 Suite 909
B14: Jakarta Pusat 10250
A16: NO | B16: DESCRIPTION | C16: PIC | D16: PIC | E16: QTY | F16: Freq | G16: Price-unit | H16: Sub Total
A18: A | B18: BOOTH PRODUCTION
A20: 1 | B20: D Day-EVENT : include preparation | D20: KIM
B21: Production & Booth team | C21: KIM | E21: 4 | F21: 1 | H21: =E21*F21*G21 -> 0
B22: PIC Foyer | C22: KIM | E22: 2 | F22: 1 | H22: =E22*F22*G22 -> 0
B23: PIC Booth | C23: KIM | E23: 2 | F23: 1 | H23: =E23*F23*G23 -> 0
B24: PIC Activity | E24: 1 | F24: 1 | H24: =E24*F24*G24 -> 0
B25: Logistic | C25: KIM | E25: 2 | F25: 2 | H25: =E25*F25*G25 -> 0
B26: Runner | C26: KIM | E26: 5 | F26: 1 | H26: =E26*F26*G26 -> 0
B27: HT | C27: KIM | E27: =E21+E22+E23+E25+E26 -> 15 | F27: 1 | H27: =E27*F27*G27 -> 0
B28: Meals - long shift | C28: KIM | E28: =E27 -> 15 | F28: 1 | H28: =E28*F28*G28 -> 0
A30: 3 | B30: Production
B32: Foyer Area:
B33: GATE (tinggi 3,6mx 3m-H) diameter 2,4m Lighted LED Flex , 2 D Pop up | D33: KIM | E33: 1 | F33: 1 | H33: =+E33*F33*G33 -> 0 | J33: 1. Booth - harga gate di kurangin dikit deh =( - 13/11
B34: Logo Lighted cutting sticker & LED Strip
B36: REGISTRATION AREA | D36: KIM | E36: 1 | F36: 1 | H36: =+E36*F36*G36 -> 0
B37: Backdrop Registration size L, size A: 4,8 x 2,44m size B ; 2,44 x 2,44m | E37: 1 | F37: 1 | H37: =+E37*F37*G37 -> 0
B38: Registration Table with IM Logo size 60x90cm | E38: 4 | F38: 1
B39: Electrical Installment for booth | C39: KIM | E39: 1 | F39: 1
B41: SIGNAGE : 2x1m , multiplex finishing sticker | D41: KIM | E41: 2 | F41: 1 | H41: =+E41*F41*G41 -> 0
B43: PHOTOBOOTH @ PartnerGathering | C43: KIM | E43: 1 | F43: 1
B44: Flooring 4,88 x 2,44m & Backdrop 4,88 x 3,6m Full finishing Flexy Print German | E44: 1 | F44: 1 | H44: =E44*F44*G44 -> 0
B45: Electrical Installment for booth | C45: KIM | E45: 1 | F45: 1 | H45: =E45*F45*G45 -> 0
B47: SMURF(Communication) Booth size 4x4m H: 3m& PODCAST | C47: KIM | E47: 1 | F47: 1 | H47: =+E47*F47*G47 -> 0
B48: Dinding Size 3x3 | E48: 1 | F48: 1 | H48: =+E48*F48*G48 -> 0
B49: Level Flooring 10cm - Melaminto 3x3m | C49: KIM | E49: 1 | F49: 1 | H49: =+E49*F49*G49 -> 0
B50: Electrical Installment for booth | C50: KIM | E50: 1 | F50: 1
B51: Podcast Equipment - 8.00 -17.00 | C51: KIM | E51: 1 | F51: 1 | H51: =+E51*F51*G51 -> 0 | J51: KENAPA DI SINI ADA PODCAST EQUPIMNET DAN ADA DI CUST EVENT YG LIVE STREAMING APAKAH DOUBLE - 13/11 - tdk double… tetep di harga 12 juta
B52: LED Table rental | E52: 2 | F52: 1 | H52: =+E52*F52*G52 -> 0
B53: Puff LED | E53: 4 | F53: 1 | H53: =+E53*F53*G53 -> 0
B54: WhiteTable rental | E54: 1 | F54: 1 | H54: =+E54*F54*G54 -> 0
B55: Showcase Consumer Products & Transportation from IM | C55: KIM | E55: 1 | F55: 1 | H55: =+E55*F55*G55 -> 0
B57: CYBER SECURITY Booth size 3x3m H:3m | C57: KIM | E57: 1 | F57: 1 | H57: =+E57*F57*G57 -> 0 | J57: 1. Booth - harga booth cyber disamakan - 15.500 - 13/11
B58: Electrical Installment for booth | C58: KIM | E58: 1 | F58: 1
...

Sheet Hackathon
H7: KIM
A15: Date | B15: : 07 Oct 2025 | E15: Project | F15: : Ingram Micro Innovation Day 2025
A16: Attn | B16: : Abigail Laurencia | E16: Date | F16: : 03 Dec 2025 (Wed)
A17: Client | B17: : PT Ingram Micro Indonesia | E17: Venue | F17: : Shangri-La Hotel, Jakarta
A18: Address | B18: : Jl. Ir. H. Juanda IV No 3B-C | E18: No. Order | F18: : QTN/KIM/2025/VIII/00015 H
B19: Wisma Nugra Santana Lt. 9 Suite 909
B20: Jakarta Pusat 10250
A23: NO | B23: DESCRIPTION | C23: PIC | D23: QTY | E23: Freq | F23: Price-unit | G23: Sub Total
A25: A | B25: Ingram Micro Innovation Day 2025
B26: Hackathon Event
A28: 1 | B28: Venue
B29: Alt 1 .Full Day Package @ Ashley Tanah Abang - dibagi 3 room | C29: KIM | D29: 50 | E29: 1 | F29: 550000 | G29: =D29*E29*F29 -> 27500000
B30: Alt 2: Full Day Package @ Pullman ; dibagi 3 Room | D30: 50 | E30: 1 | F30: 950000
B31: Alt 3: Full Day Package @ Shangri-La ; dibagi 3 Room | D31: 50 | E31: 1 | F31: 1000000
B32: Classroom table - 1 table 3 chairs | D32: 16 | E32: 1
B33: LCD Projector + Screen
B34: Stage Module
B36: D Day-EVENT : include preparation | C36: KIM | D36: 1 | E36: 1 | F36: 37500000 | G36: =D36*E36*F36 -> 37500000
B37: Team work : Project Officer , SD, VJ, LO MC, Stage Mgr, Crew | D37: 1 | E37: 1 | G37: =D37*E37*F37 -> 0
B38: LO Group | D38: 1 | E38: 1
B39: Facilitator per category | D39: 1 | E39: 1 | G39: =D39*E39*F39 -> 0
B40: MC | D40: 1 | E40: 1
B41: Runner | D41: 1 | E41: 1 | G41: =D41*E41*F41 -> 0
B42: Mentor /category | D42: 3 | E42: 1
B43: Independent Judges/category | C43: KIM | D43: 3 | E43: 1 | F43: 12500000 | G43: =D43*E43*F43 -> 37500000
B44: Microsite Hackathon - One link to IMID website | C44: KIM | D44: 1 | E44: 1 | F44: 1500000 | G44: =D44*E44*F44 -> 1500000
A46: 2 | B46: Documentation on D Day event
B47: Photografer | C47: KIM | D47: 1 | E47: 1 | F47: 1750000 | G47: =D47*E47*F47 -> 1750000
B48: Video For Documentation include highlight editing | C48: KIM | D48: 1 | E48: 1 | F48: 3000000 | G48: =D48*E48*F48 -> 3000000
A50: 3 | B50: Creative
B51: Bumper Still for speaker, Design EDM , IG | C51: KIM | D51: 1 | E51: 1 | F51: 2500000 | G51: =D51*E51*F51 -> 2500000
A53: 4 | B53: Production
B54: Roll up Banner for 3 rooms | C54: KIM | D54: 6 | E54: 1 | F54: 750000 | G54: =+D54*E54*F54 -> 4500000
B55: Backdrop Photobooth | C55: KIM | D55: 1 | E55: 1 | F55: 5000000 | G55: =+D55*E55*F55 -> 5000000
B56: LED size 2x 3,5m based 40cm | C56: KIM | D56: 3 | E56: 1 | F56: 8500000 | G56: =+D56*E56*F56 -> 25500000
B57: Backdrop ki ka LED size 1,2 x 2m | C57: KIM | D57: 6 | E57: 1 | F57: 2250000 | G57: =+D57*E57*F57 -> 13500000
B58: Sound System for Main brief 1,500 watt | C58: KIM | D58: 1 | E58: 1 | F58: 3000000 | G58: =+D58*E58*F58 -> 3000000
B59: Sound System for other 2 BO rooms - standart - from Hotel
B60: Signage Registration & Agenda Size A1 , Tripod | C60: KIM | D60: 1 | E60: 1 | F60: 550000 | G60: =+D60*E60*F60 -> 550000
B61: TV for Agenda info (55') + standee @ Registration area | C61: KIM | D61: 1 | E61: 1 | F61: 1750000 | G61: =+D61*E61*F61 -> 1750000
...

Sheet Summary
B6: Description | C6: Total Budget | D6: ASF | E6: Grand Total
B7: KOL Sosmed | C7: ='KOL SocMed '!F39 -> 31000000 | D7: ='KOL SocMed '!F40 -> 0 | E7: =+C7+D7 -> 31000000
B8: PR Package BEM | C8: ='PR Package BEM'!G79 -> 45000000 | D8: =C8*10% -> 4500000 | E8: =+C8+D8 -> 49500000
B9: Registration | C9: =Registration!G33 -> 8000000 | D9: =C9*10% -> 800000 | E9: =+C9+D9 -> 8800000
B10: Customer Event | C10: ='Customer Event'!G107 -> 151076922 | D10: =C10*10% -> 15107692 | E10: =+C10+D10 -> 1.6618461e+08
B11: Partner Event | C11: ='Partner Event'!G67 -> 22500000 | D11: =C11*10% -> 2250000 | E11: =+C11+D11 -> 24750000
B12: Booth | C12: =Booth!H130 -> 0 | D12: =C12*10% -> 0 | E12: =+C12+D12 -> 0
E14: =SUM(E7:E13) -> 2.8023461e+08
